Title: 676018 – dev-python/pytest-xdist-1.23.2: fails 8 tests
URL: https://bugs.gentoo.org/show_bug.cgi?id=676018

Go to: 
		Gentoo Home
Documentation
Forums
Lists
Bugs
Planet
Store
Wiki
Get Gentoo!





Gentoo's Bugzilla – Bug 676018
dev-python/pytest-xdist-1.23.2: fails 8 tests
Last modified: 2019-01-29 00:21:35 UTC node [vulture]


Home
| New–[Ex]
| Browse
| Search
| Privacy Policy

| 





[?]
| Reports

| 
Requests

| 
Help


| 
New Account


| 
Log In





[x]



| 
Forgot Password

Login:




[x]













Bug 676018 
      - dev-python/pytest-xdist-1.23.2: fails 8 tests


Summary:
dev-python/pytest-xdist-1.23.2: fails 8 tests
    








Status:
    

RESOLVED
          WORKSFORME
      






Alias:


        None
    





Product:

Gentoo Linux




Classification:

Unclassified




Component:

Current packages

  (show other bugs)



Hardware:

PPC
        Linux
      







Importance:
      
Normal
       normal
      


Assignee:

Python Gentoo Team








URL:







Whiteboard:




Keywords:

TESTFAILURE







Depends on:







Blocks:









 





      Reported:
    
2019-01-22 02:01 UTC by ernsteiswuerfel





      Modified:
    
2019-01-29 00:21 UTC
      (History)
    




          CC List:
        

0 
          users
        








See Also:






Package list:







Runtime testing required:

---























      Attachments
    




build.log

              (pytest-xdist-1.23.2:20190122-015305.log,67.62 KB,
                text/plain)

            
2019-01-22 02:01 UTC,

            ernsteiswuerfel




Details





emerge --info

              (file_676018.txt,5.89 KB,
                text/plain)

            
2019-01-22 02:02 UTC,

            ernsteiswuerfel




Details





View All

Add an attachment
        (proposed patch, testcase, etc.)
    








Note
              You need to
              log in
              before you can comment on or make changes to this bug.
            

















Description


ernsteiswuerfel






          2019-01-22 02:01:33 UTC
        

Created attachment 562500 [details]
build.log

FAIL testing/acceptance_test.py::TestDistribution::()::test_keyboardinterrupt_hooks_issue79
FAIL testing/test_looponfail.py::TestRemoteControl::()::test_nofailures
FAIL testing/test_looponfail.py::TestRemoteControl::()::test_failures_somewhere
FAIL testing/test_looponfail.py::TestRemoteControl::()::test_failure_change
FAIL testing/test_looponfail.py::TestRemoteControl::()::test_failure_subdir_no_init
FAIL testing/test_looponfail.py::TestLooponFailing::()::test_looponfail_from_fail_to_ok
FAIL testing/test_looponfail.py::TestLooponFailing::()::test_looponfail_from_one_to_two_tests
FAIL testing/test_looponfail.py::TestLooponFailing::()::test_looponfail_multiple_errors




Comment 1


ernsteiswuerfel






          2019-01-22 02:02:03 UTC
        

Created attachment 562502 [details]
emerge --info




Comment 2


ernsteiswuerfel






          2019-01-29 00:21:35 UTC
        

Strange... now I can't reproduce this any longer. All tests are passed.

Will close and re-open if I hit this issue again.









Format For Printing
 - XML
 - Clone This Bug
 - Clone In The Same 
                        Product
 - Top of page 







Home
| New–[Ex]
| Browse
| Search
| Privacy Policy

| 





[?]
| Reports

| 
Requests

| 
Help


| 
New Account


| 
Log In





[x]



| 
Forgot Password

Login:




[x]

